Workbook

Sheet Cover
A1: Financial Model: Aurora Retail Co.
A2: Prepared with Finance Studio on 10/29/2026
A3: Blue = input you can change · Green = linked to Historicals · Black = formula
A5: Source data | B5: Aurora Retail Co. · 2020–2024 (5 periods)
A7: Contents
A8: Sheet | B8: What it contains
A9: Historicals | B9: Your uploaded financial statements (the source for linked figures)
A10: DCF | B10: Discounted cash flow valuation with sensitivity table
A11: Comps | B11: Trading comparables: implied valuation range
A12: WACC | B12: Weighted average cost of capital (CAPM)
A13: MonteCarlo | B13: Monte Carlo valuation range (simulation results)
A14: LBO | B14: Leveraged buyout: sources & uses, debt schedule, IRR and MOIC
A15: Loan | B15: Amortizing loan schedule
A16: NPV_IRR | B16: Investment appraisal: NPV, IRR, MIRR, payback
A17: Breakeven | B17: Break-even units, revenue and margin of safety
A18: Feasibility | B18: Project feasibility: cash flows, NPV, IRR, payback, verdict
A19: Ratios | B19: Ratio analysis linked to Historicals
A20: Forecast | B20: 3-statement style forecast: P&L, cash and debt
A22: How to use this model
A23: Input | B23: Blue cells are inputs. Change them and every formula updates.
A24: Linked | B24: Green cells link to the Historicals sheet.
A25: Formula | B25: Black cells are formulas. Avoid typing over them.
A26: Output | B26: Shaded cells are key outputs.
A28: Models are planning tools based on the data and assumptions provided. They are not investment advice.

Sheet Historicals
A1: Historical Financial Statements
A2: Aurora Retail Co. · as uploaded
A3: Blue = input you can change · Green = linked to Historicals · Black = formula
A5: Financial statements
A6: Line item | B6: 2020 | C6: 2021 | D6: 2022 | E6: 2023 | F6: 2024
A7: Revenue | B7: 8200000 | C7: 9100000 | D7: 10400000 | E7: 11800000 | F7: 13100000
A8: Cost of Goods Sold | B8: 4900000 | C8: 5400000 | D8: 6100000 | E8: 6800000 | F8: 7500000
A9: Gross Profit | B9: 3300000 | C9: 3700000 | D9: 4300000 | E9: 5000000 | F9: 5600000
A10: Operating Expenses | B10: 1800000 | C10: 1950000 | D10: 2150000 | E10: 2400000 | F10: 2600000
A11: EBITDA | B11: 1500000 | C11: 1750000 | D11: 2150000 | E11: 2600000 | F11: 3000000
A12: D&A | B12: 300000 | C12: 330000 | D12: 360000 | E12: 400000 | F12: 440000
A13: EBIT | B13: 1200000 | C13: 1420000 | D13: 1790000 | E13: 2200000 | F13: 2560000
A14: Interest Expense | B14: 180000 | C14: 170000 | D14: 160000 | E14: 150000 | F14: 140000
A15: Net Income | B15: 765000 | C15: 937500 | D15: 1222500 | E15: 1537500 | F15: 1815000
A16: Cash | B16: 900000 | C16: 1100000 | D16: 1400000 | E16: 1800000 | F16: 2300000
A17: Current Assets | B17: 3100000 | C17: 3500000 | D17: 4000000 | E17: 4600000 | F17: 5300000
A18: Total Assets | B18: 9500000 | C18: 10300000 | D18: 11400000 | E18: 12600000 | F18: 14000000
... A24: Operating Cash Flow | B24: 1200000 | C24: 1400000 | D24: 1700000 | E24: 2000000 | F24: 2400000

Sheet DCF
A1: DCF Valuation
A2: Aurora Retail Co. · discounted cash flow
A3: Blue = input you can change · Green = linked to Historicals · Black = formula
A5: Assumptions
A6: Base revenue (last actual year) | B6: =Historicals!$F$7 -> 13100000
A7: Revenue growth | B7: 0.124
A8: EBITDA margin | B8: 0.229
A9: D&A % of revenue | B9: 0.034
A10: CapEx % of revenue | B10: 0.061
A11: Working capital % of new revenue | B11: 0.1
A12: Tax rate | B12: 0.25
A13: WACC (discount rate) | B13: 0.1
A14: Terminal growth | B14: 0.025
A15: Net debt | B15: =Historicals!$F$21-Historicals!$F$16 -> -100000 | C15: Total debt less cash
A16: Shares outstanding | B16: 1000000
A18: Free cash flow projection
A19: Fiscal year | B19: 2025E | C19: 2026E | D19: 2027E | E19: 2028E | F19: 2029E
A20: Revenue | B20: =$B$6*(1+$B$7) -> 14724400 | C20: =B20*(1+$B$7) -> 16550226 | D20: =C20*(1+$B$7) -> 18602454 | E20: =D20*(1+$B$7) -> 20909158 | F20: =E20*(1+$B$7) -> 23501893
A21: EBITDA | B21: =B20*$B$8 -> 3371887.6 | C21: =C20*$B$8 -> 3790001.7 | D21: =D20*$B$8 -> 4259961.9 | E21: =E20*$B$8 -> 4788197.1 | F21: =F20*$B$8 -> 5381933.6
A22: Depreciation & amortization | B22: =B20*$B$9 -> 500629.6 | C22: =C20*$B$9 -> 562707.67 | D22: =D20*$B$9 -> 632483.42 | E22: =E20*$B$9 -> 710911.37 | F22: =F20*$B$9 -> 799064.38
A23: EBIT | B23: =B21-B22 -> 2871258 | C23: =C21-C22 -> 3227294 | D23: =D21-D22 -> 3627478.4 | E23: =E21-E22 -> 4077285.8 | F23: =F21-F22 -> 4582869.2
A24: Taxes on EBIT | B24: =B23*$B$12 -> 717814.5 | C24: =C23*$B$12 -> 806823.5 | D24: =D23*$B$12 -> 906869.61 | E24: =E23*$B$12 -> 1019321.4 | F24: =F23*$B$12 -> 1145717.3
A25: NOPAT | B25: =B23-B24 -> 2153443.5 | C25: =C23-C24 -> 2420470.5 | D25: =D23-D24 -> 2720608.8 | E25: =E23-E24 -> 3057964.3 | F25: =F23-F24 -> 3437151.9
A26: Capital expenditure | B26: =B20*$B$10 -> 898188.4 | C26: =C20*$B$10 -> 1009563.8 | D26: =D20*$B$10 -> 1134749.7 | E26: =E20*$B$10 -> 1275458.6 | F26: =F20*$B$10 -> 1433615.5
A27: Increase in working capital | B27: =(B20-$B$6)*$B$11 -> 162440 | C27: =(C20-B20)*$B$11 -> 182582.56 | D27: =(D20-C20)*$B$11 -> 205222.8 | E27: =(E20-D20)*$B$11 -> 230670.42 | F27: =(F20-E20)*$B$11 -> 259273.56
A28: Unlevered free cash flow | B28: =B25+B22-B26-B27 -> 1593444.7 | C28: =C25+C22-C26-C27 -> 1791031.8 | D28: =D25+D22-D26-D27 -> 2013119.8 | E28: =E25+E22-E26-E27 -> 2262746.6 | F28: =F25+F22-F26-F27 -> 2543327.2
A29: Discount factor | B29: =1/(1+$B$13)^1 -> 0.90909091 | C29: =1/(1+$B$13)^2 -> 0.82644628 | D29: =1/(1+$B$13)^3 -> 0.7513148 | E29: =1/(1+$B$13)^4 -> 0.68301346 | F29: =1/(1+$B$13)^5 -> 0.62092132
A30: Present value of FCF | B30: =B28*B29 -> 1448586.1 | C30: =C28*C29 -> 1480191.6 | D30: =D28*D29 -> 1512486.7 | E30: =E28*E29 -> 1545486.4 | F30: =F28*F29 -> 1579206.1
A32: Valuation
A33: Sum of PV of free cash flows | B33: =SUM(B30:F30) -> 7565956.9
A34: Terminal value (Gordon growth) | B34: =F28*(1+$B$14)/($B$13-$B$14) -> 34758805
A35: PV of terminal value | B35: =B34*F29 -> 21582483
A36: Enterprise value | B36: =B33+B35 -> 29148440
A37: Less: net debt | B37: =$B$15 -> -100000
A38: Equity value | B38: =B36-B37 -> 29248440
A39: Value per share | B39: =B38/$B$16 -> 29.24844
A40: Terminal value as % of EV | B40: =B35/B36 -> 0.74043356
A42: Sensitivity: enterprise value
A43: WACC ↓ Terminal growth → | B43: =$B$14+-0.01 -> 0.015 | C43: =$B$14+-0.005 -> 0.02 | D43: =$B$14+0 -> 0.025 | E43: =$B$14+0.005 -> 0.03 | F43: =$B$14+0.01 -> 0.035
A44: =$B$13+-0.02 -> 0.08 | B44: =NPV($A44,$B$28:$F$28)+$F$28*(1+B$43)/($A44-B$43)/(1+$A44)^5 -> 35032528 | C44: =NPV($A44,$B$28:$F$28)+$F$28*(1+C$43)/($A44-C$43)/(1+$A44)^5 -> 37429223 | D44: =NPV($A44,$B$28:$F$28)+$F$28*(1+D$43)/($A44-D$43)/(1+$A44)^5 -> 40261679 | E44: =NPV($A44,$B$28:$F$28)+$F$28*(1+E$43)/($A44-E$43)/(1+$A44)^5 -> 43660627 | F44: =NPV($A44,$B$28:$F$28)+$F$28*(1+F$43)/($A44-F$43)/(1+$A44)^5 -> 47814897
...

Sheet Comps
A1: Comparable Companies
A2: Aurora Retail Co. · trading multiples
A3: Blue = input you can change · Green = linked to Historicals · Black = formula
A5: Company metrics
A6: Revenue | B6: =Historicals!$F$7 -> 13100000
A7: EBITDA | B7: =Historicals!$F$11 -> 3000000
A8: Net income | B8: =Historicals!$F$15 -> 1815000
A9: Net debt | B9: =Historicals!$F$21-Historicals!$F$16 -> -100000
A11: Peer multiples (enter your peer group)
A12: Peer | B12: EV / EBITDA | C12: EV / Sales | D12: P / E
A13: Peer 1 | B13: 7.5 | C13: 1.1 | D13: 14
A14: Peer 2 | B14: 8.2 | C14: 1.4 | D14: 16.5
A15: Peer 3 | B15: 9 | C15: 1.6 | D15: 18
A16: Peer 4 | B16: 10.1 | C16: 1.9 | D16: 21
A17: Peer 5 | B17: 11.4
A19: Implied equity value
A20: Method | B20: Low multiple | C20: Median multiple | D20: High multiple | E20: Low value | F20: Median value | G20: High value
A21: EV / EBITDA | B21: =MIN(B$13:B$17) -> 7.5 | C21: =MEDIAN(B$13:B$17) -> 9 | D21: =MAX(B$13:B$17) -> 11.4 | E21: =B21*$B$7-$B$9 -> 22600000 | F21: =C21*$B$7-$B$9 -> 27100000 | G21: =D21*$B$7-$B$9 -> 34300000
A22: EV / Sales | B22: =MIN(C$13:C$17) -> 1.1 | C22: =MEDIAN(C$13:C$17) -> 1.5 | D22: =MAX(C$13:C$17) -> 1.9 | E22: =B22*$B$6-$B$9 -> 14510000 | F22: =C22*$B$6-$B$9 -> 19750000 | G22: =D22*$B$6-$B$9 -> 24990000
A23: P / E | B23: =MIN(D$13:D$17) -> 14 | C23: =MEDIAN(D$13:D$17) -> 17.25 | D23: =MAX(D$13:D$17) -> 21 | E23: =B23*$B$8 -> 25410000 | F23: =C23*$B$8 -> 31308750 | G23: =D23*$B$8 -> 38115000
A25: Implied equity value (median of methods) | B25: =MEDIAN(F21,F22,F23) -> 27100000

Sheet WACC
A1: Weighted Average Cost of Capital
A2: Aurora Retail Co. · discount rate
A3: Blue = input you can change · Green = linked to Historicals · Black = formula
A5: Assumptions
A6: Equity value | B6: =Historicals!$F$22 -> 8200000
A7: Debt value | B7: =Historicals!$F$21 -> 2200000
A8: Risk-free rate | B8: 0.042
A9: Beta | B9: 1.1
A10: Market risk premium | B10: 0.055
A11: Size / specific risk premium | B11: 0.01
A12: Pre-tax cost of debt | B12: 0.064
A13: Tax rate | B13: 0.25
A15: Calculation
A16: Cost of equity (CAPM) | B16: =$B$8+$B$9*$B$10+$B$11 -> 0.1125
A17: After-tax cost of debt | B17: =$B$12*(1-$B$13) -> 0.048
A18: Equity weight (E / V) | B18: =$B$6/($B$6+$B$7) -> 0.78846154
A19: Debt weight (D / V) | B19: =$B$7/($B$6+$B$7) -> 0.21153846
A20: WACC | B20: =B18*B16+B19*B17 -> 0.098855769

Sheet MonteCarlo
A1: Monte Carlo Valuation
A2: Aurora Retail Co. · simulated DCF outcomes
A3: Blue = input you can change · Green = linked to Historicals · Black = formula
A5: Assumptions used in the simulation
A6: Base revenue | B6: 13100000
A7: Growth mean | B7: 0.124
A8: Growth std. dev. | B8: 0.03
A9: EBITDA margin mean | B9: 0.229
A10: Margin std. dev. | B10: 0.03
A11: WACC | B11: 0.1
A12: Terminal growth | B12: 0.025
A13: Net debt | B13: -100000
A14: Simulations | B14: 2000
A15: Results below were simulated in Finance Studio. Change the assumptions in the app and export again to re-run.
A17: Results: enterprise value
A18: P10 (downside) | B18: 20654739
A19: P50 (median) | B19: 28867040
A20: P90 (upside) | B20: 38211664
A21: Base case (no randomness) | B21: 29148440
A22: Probability above base case | B22: 0.4825
A24: Distribution
A25: Bucket | B25: From | C25: To | D25: Simulations
A26: Bucket 1 | B26: 14920729 | C26: 16303742 | D26: 24
A27: Bucket 2 | B27: 16303742 | C27: 17686755 | D27: 31
A28: Bucket 3 | B28: 17686755 | C28: 19069769 | D28: 52
A29: Bucket 4 | B29: 19069769 | C29: 20452782 | D29: 58
A30: Bucket 5 | B30: 20452782 | C30: 21835795 | D30: 102
A31: Bucket 6 | B31: 21835795 | C31: 23218809 | D31: 99
A32: Bucket 7 | B32: 23218809 | C32: 24601822 | D32: 128
A33: Bucket 8 | B33: 24601822 | C33: 25984835 | D33: 148
A34: Bucket 9 | B34: 25984835 | C34: 27367849 | D34: 154
A35: Bucket 10 | B35: 27367849 | C35: 28750862 | D35: 174
A36: Bucket 11 | B36: 28750862 | C36: 30133875 | D36: 157
A37: Bucket 12 | B37: 30133875 | C37: 31516889 | D37: 148
... A49: Bucket 24 | B49: 46730035 | C49: 48113048 | D49: 10

Sheet LBO
A1: Leveraged Buyout
A2: Aurora Retail Co. · sponsor returns
A3: Blue = input you can change · Green = linked to Historicals · Black = formula
A5: Assumptions
A6: Entry EBITDA | B6: =Historicals!$F$11 -> 3000000
A7: Entry multiple (x EBITDA) | B7: 8
A8: Debt (x EBITDA) | B8: 4.5
A9: Interest rate | B9: 0.08
A10: EBITDA growth | B10: 0.124
A11: Exit multiple (x EBITDA) | B11: 8
A12: Tax rate | B12: 0.25
A13: CapEx % of EBITDA | B13: 0.15
A14: Cash used to repay debt | B14: 1
A15: Transaction fees % of EV | B15: 0.02
A17: Sources & uses
A18: Purchase price (enterprise value) | B18: =$B$6*$B$7 -> 24000000
A19: Transaction fees | B19: =B18*$B$15 -> 480000
A20: Total uses | B20: =B18+B19 -> 24480000
A21: Debt raised | B21: =$B$6*$B$8 -> 13500000
A22: Sponsor equity | B22: =B20-B21 -> 10980000
A24: Debt schedule
B25: Entry | C25: 2025E | D25: 2026E | E25: 2027E | F25: 2028E | G25: 2029E
A26: EBITDA | B26: =$B$6 -> 3000000 | C26: =B26*(1+$B$10) -> 3372000 | D26: =C26*(1+$B$10) -> 3790128 | E26: =D26*(1+$B$10) -> 4260103.9 | F26: =E26*(1+$B$10) -> 4788356.8 | G26: =F26*(1+$B$10) -> 5382113
A27: Interest | C27: =B32*$B$9 -> 1080000 | D27: =C32*$B$9 -> 972828 | E27: =D32*$B$9 -> 837901.15 | F27: =E32*$B$9 -> 670909.92 | G27: =F32*$B$9 -> 466958.32
A28: Capital expenditure | C28: =C26*$B$13 -> 505800 | D28: =D26*$B$13 -> 568519.2 | E28: =E26*$B$13 -> 639015.58 | F28: =F26*$B$13 -> 718253.51 | G28: =G26*$B$13 -> 807316.95
A29: Taxes | C29: =MAX(0,(C26-C27-C28)*$B$12) -> 446550 | D29: =MAX(0,(D26-D27-D28)*$B$12) -> 562195.2 | E29: =MAX(0,(E26-E27-E28)*$B$12) -> 695796.78 | F29: =MAX(0,(F26-F27-F28)*$B$12) -> 849798.33 | G29: =MAX(0,(G26-G27-G28)*$B$12) -> 1026959.4
A30: Free cash flow | C30: =C26-C27-C28-C29 -> 1339650 | D30: =D26-D27-D28-D29 -> 1686585.6 | E30: =E26-E27-E28-E29 -> 2087390.4 | F30: =F26-F27-F28-F29 -> 2549395 | G30: =G26-G27-G28-G29 -> 3080878.3
A31: Debt repayment | C31: =MIN(B32,MAX(0,C30*$B$14)) -> 1339650 | D31: =MIN(C32,MAX(0,D30*$B$14)) -> 1686585.6 | E31: =MIN(D32,MAX(0,E30*$B$14)) -> 2087390.4 | F31: =MIN(E32,MAX(0,F30*$B$14)) -> 2549395 | G31: =MIN(F32,MAX(0,G30*$B$14)) -> 3080878.3
A32: Debt balance (end of year) | B32: =B21 -> 13500000 | C32: =B32-C31 -> 12160350 | D32: =C32-D31 -> 10473764 | E32: =D32-E31 -> 8386374 | F32: =E32-F31 -> 5836979.1 | G32: =F32-G31 -> 2756100.8
A33: Cash balance | B33: 0 | C33: =B33+C30-C31 -> 0 | D33: =C33+D30-D31 -> 0 | E33: =D33+E30-E31 -> 0 | F33: =E33+F30-F31 -> 0 | G33: =F33+G30-G31 -> 0
A34: Equity value at exit multiple | B34: =B22 -> 10980000 | C34: =C26*$B$11-C32+C33 -> 14815650 | D34: =D26*$B$11-D32+D33 -> 19847260 | E34: =E26*$B$11-E32+E33 -> 25694457 | F34: =F26*$B$11-F32+F33 -> 32469875 | G34: =G26*$B$11-G32+G33 -> 40300803
A36: Returns
A37: Exit equity value | B37: =G34 -> 40300803
A38: MOIC (multiple of invested capital) | B38: =B37/B22 -> 3.6703828
A39: IRR | B39: =MAX(0,B38)^(1/5)-1 -> 0.29700686

Sheet Loan
A1: Loan Amortization Schedule
A2: Aurora Retail Co. · debt service
A3: Blue = input you can change · Green = linked to Historicals · Black = formula
A5: Assumptions
A6: Loan amount | B6: =Historicals!$F$21 -> 2200000
A7: Annual interest rate | B7: 0.064
A8: Term (years) | B8: 7
A9: Payments per year | B9: 12
A11: Payment
A12: Periodic interest rate | B12: =$B$7/$B$9 -> 0.0053333333
A13: Number of payments | B13: =$B$8*$B$9 -> 84
A14: Payment per period | B14: =PMT($B$12,$B$13,-$B$6) -> 32562.356
A15: Total paid | B15: =$B$14*$B$13 -> 2735237.9
A16: Total interest | B16: =B15-$B$6 -> 535237.9
A18: Annual schedule
A19: Year | B19: Opening balance | C19: Payments | D19: Interest | E19: Principal | F19: Closing balance
A20: 1 | B20: =$B$6 -> 2200000 | C20: =$B$14*$B$9 -> 390748.27 | D20: =C20-E20 -> 133336.26 | E20: =B20-F20 -> 257412.01 | F20: =MAX(0,$B$6*(1+$B$12)^(1*$B$9)-$B$14*((1+$B$12)^(1*$B$9)-1)/$B$12) -> 1942588
A21: 2 | B21: =F20 -> 1942588 | C21: =$B$14*$B$9 -> 390748.27 | D21: =C21-E21 -> 116369.95 | E21: =B21-F21 -> 274378.32 | F21: =MAX(0,$B$6*(1+$B$12)^(2*$B$9)-$B$14*((1+$B$12)^(2*$B$9)-1)/$B$12) -> 1668209.7
A22: 3 | B22: =F21 -> 1668209.7 | C22: =$B$14*$B$9 -> 390748.27 | D22: =C22-E22 -> 98285.371 | E22: =B22-F22 -> 292462.9 | F22: =MAX(0,$B$6*(1+$B$12)^(3*$B$9)-$B$14*((1+$B$12)^(3*$B$9)-1)/$B$12) -> 1375746.8
A23: 4 | B23: =F22 -> 1375746.8 | C23: =$B$14*$B$9 -> 390748.27 | D23: =C23-E23 -> 79008.816 | E23: =B23-F23 -> 311739.45 | F23: =MAX(0,$B$6*(1+$B$12)^(4*$B$9)-$B$14*((1+$B$12)^(4*$B$9)-1)/$B$12) -> 1064007.3
A24: 5 | B24: =F23 -> 1064007.3 | C24: =$B$14*$B$9 -> 390748.27 | D24: =C24-E24 -> 58461.722 | E24: =B24-F24 -> 332286.55 | F24: =MAX(0,$B$6*(1+$B$12)^(5*$B$9)-$B$14*((1+$B$12)^(5*$B$9)-1)/$B$12) -> 731720.77
A25: 6 | B25: =F24 -> 731720.77 | C25: =$B$14*$B$9 -> 390748.27 | D25: =C25-E25 -> 36560.346 | E25: =B25-F25 -> 354187.92 | F25: =MAX(0,$B$6*(1+$B$12)^(6*$B$9)-$B$14*((1+$B$12)^(6*$B$9)-1)/$B$12) -> 377532.84
A26: 7 | B26: =F25 -> 377532.84 | C26: =$B$14*$B$9 -> 390748.27 | D26: =C26-E26 -> 13215.426 | E26: =B26-F26 -> 377532.84 | F26: =MAX(0,$B$6*(1+$B$12)^(7*$B$9)-$B$14*((1+$B$12)^(7*$B$9)-1)/$B$12) -> 4.6566129e-10

Sheet NPV_IRR
A1: NPV / IRR Investment Appraisal
A2: Aurora Retail Co. · project returns
A3: Blue = input you can change · Green = linked to Historicals · Black = formula
A5: Assumptions
A6: Initial investment | B6: 6000000
A7: Discount rate | B7: 0.1
A8: Reinvestment rate (MIRR) | B8: 0.08
A10: Cash flows (enter yearly cash flows in blue)
B11: Year 0 | C11: Year 1 | D11: Year 2 | E11: Year 3 | F11: Year 4 | G11: Year 5
A12: Cash flow | B12: =-$B$6 -> -6000000 | C12: 1575000 | D12: 1653750 | E12: 1736438 | F12: 1823259 | G12: 1914422
A13: Discount factor | B13: =1/(1+$B$7)^0 -> 1 | C13: =1/(1+$B$7)^1 -> 0.90909091 | D13: =1/(1+$B$7)^2 -> 0.82644628 | E13: =1/(1+$B$7)^3 -> 0.7513148 | F13: =1/(1+$B$7)^4 -> 0.68301346 | G13: =1/(1+$B$7)^5 -> 0.62092132
A14: Discounted cash flow | B14: =B12*B13 -> -6000000 | C14: =C12*C13 -> 1431818.2 | D14: =D12*D13 -> 1366735.5 | E14: =E12*E13 -> 1304611.6 | F14: =F12*F13 -> 1245310.4 | G14: =G12*G13 -> 1188705.4
A15: Cumulative cash flow | B15: =B12 -> -6000000 | C15: =B15+C12 -> -4425000 | D15: =C15+D12 -> -2771250 | E15: =D15+E12 -> -1034812 | F15: =E15+F12 -> 788447 | G15: =F15+G12 -> 2702869
A16: Cumulative discounted cash flow | B16: =B14 -> -6000000 | C16: =B16+C14 -> -4568181.8 | D16: =C16+D14 -> -3201446.3 | E16: =D16+E14 -> -1896834.7 | F16: =E16+F14 -> -651524.28 | G16: =F16+G14 -> 537181.16
A17: Payback (helper) | C17: =IF(AND(B15<0,C15>=0),0-B15/C12,0) -> 0 | D17: =IF(AND(C15<0,D15>=0),1-C15/D12,0) -> 0 | E17: =IF(AND(D15<0,E15>=0),2-D15/E12,0) -> 0 | F17: =IF(AND(E15<0,F15>=0),3-E15/F12,0) -> 3.5675617 | G17: =IF(AND(F15<0,G15>=0),4-F15/G12,0) -> 0
A18: Discounted payback (helper) | C18: =IF(AND(B16<0,C16>=0),0-B16/C14,0) -> 0 | D18: =IF(AND(C16<0,D16>=0),1-C16/D14,0) -> 0 | E18: =IF(AND(D16<0,E16>=0),2-D16/E14,0) -> 0 | F18: =IF(AND(E16<0,F16>=0),3-E16/F14,0) -> 0 | G18: =IF(AND(F16<0,G16>=0),4-F16/G14,0) -> 4.5480956
A20: Results
A21: Net present value (NPV) | B21: =B12+NPV($B$7,C12:G12) -> 537181.16
A22: Internal rate of return (IRR) | B22: =IRR(B12:G12) -> 0.13327367
A23: Modified IRR (MIRR) | B23: =MIRR(B12:G12,$B$7,$B$8) -> 0.11053948
A24: Payback period | B24: =IF(SUM(C17:G17)=0,"Never",SUM(C17:G17)) -> 3.5675617
A25: Discounted payback period | B25: =IF(SUM(C18:G18)=0,"Never",SUM(C18:G18)) -> 4.5480956
A26: Profitability index | B26: =NPV($B$7,C12:G12)/$B$6 -> 1.0895302

Sheet Breakeven
A1: Break-even Analysis
A2: Aurora Retail Co. · cost-volume-profit
A3: Blue = input you can change · Green = linked to Historicals · Black = formula
A5: Assumptions
A6: Fixed costs per year | B6: 500000
A7: Price per unit | B7: 50
A8: Variable cost per unit | B8: 30
A9: Expected units sold | B9: 40000
A11: Results
A12: Contribution margin per unit | B12: =$B$7-$B$8 -> 20
A13: Break-even units | B13: =$B$6/B12 -> 25000
A14: Break-even revenue | B14: =B13*$B$7 -> 1250000
A15: Expected profit | B15: =$B$9*B12-$B$6 -> 300000
A16: Margin of safety | B16: =($B$9-B13)/$B$9 -> 0.375
A17: Operating leverage | B17: =$B$9*B12/B15 -> 2.6666667

Sheet Feasibility
A1: Feasibility Report: New Store Expansion
A2: Investment appraisal of a new project
A3: Blue = input you can change · Green = linked to Historicals · Black = formula
A5: Assumptions
A6: Initial investment | B6: 2000000
A7: Year-1 revenue | B7: 1200000
A8: Revenue growth | B8: 0.06
A9: Variable costs % of revenue | B9: 0.45
A10: Fixed costs per year | B10: 250000
A11: Project life (years) | B11: 10 | C11: Changing the life needs a new export (columns are fixed)
A12: Discount rate / hurdle | B12: 0.1
A13: Tax rate | B13: 0.25
A14: Salvage value at end | B14: 200000
A16: Projected cash flows
B17: Year 0 | C17: Year 1 | D17: Year 2 | E17: Year 3 | F17: Year 4 | G17: Year 5 | H17: Year 6 | I17: Year 7 | J17: Year 8 | K17: Year 9 | L17: Year 10
A18: Revenue | C18: =$B$7*(1+$B$8)^0 -> 1200000 | D18: =$B$7*(1+$B$8)^1 -> 1272000 | E18: =$B$7*(1+$B$8)^2 -> 1348320 | F18: =$B$7*(1+$B$8)^3 -> 1429219.2 | G18: =$B$7*(1+$B$8)^4 -> 1514972.4 | H18: =$B$7*(1+$B$8)^5 -> 1605870.7 | I18: =$B$7*(1+$B$8)^6 -> 1702222.9 | J18: =$B$7*(1+$B$8)^7 -> 1804356.3 | K18: =$B$7*(1+$B$8)^8 -> 1912617.7 | L18: =$B$7*(1+$B$8)^9 -> 2027374.8
A19: Variable costs | C19: =C18*$B$9 -> 540000 | D19: =D18*$B$9 -> 572400 | E19: =E18*$B$9 -> 606744 | F19: =F18*$B$9 -> 643148.64 | G19: =G18*$B$9 -> 681737.56 | H19: =H18*$B$9 -> 722641.81 | I19: =I18*$B$9 -> 766000.32 | J19: =J18*$B$9 -> 811960.34 | ... L19: =L18*$B$9 -> 912318.64
A20: Fixed costs | C20: =$B$10 -> 250000 | D20: =$B$10 -> 250000 | E20: =$B$10 -> 250000 | F20: =$B$10 -> 250000 | G20: =$B$10 -> 250000 | H20: =$B$10 -> 250000 | I20: =$B$10 -> 250000 | J20: =$B$10 -> 250000 | ... L20: =$B$10 -> 250000
A21: EBITDA | C21: =C18-C19-C20 -> 410000 | D21: =D18-D19-D20 -> 449600 | E21: =E18-E19-E20 -> 491576 | F21: =F18-F19-F20 -> 536070.56 | G21: =G18-G19-G20 -> 583234.79 | H21: =H18-H19-H20 -> 633228.88 | I21: =I18-I19-I20 -> 686222.61 | J21: =J18-J19-J20 -> 742395.97 | ... L21: =L18-L19-L20 -> 865056.11
A22: Depreciation (tax) | C22: =($B$6-$B$14)/$B$11 -> 180000 | D22: =($B$6-$B$14)/$B$11 -> 180000 | E22: =($B$6-$B$14)/$B$11 -> 180000 | F22: =($B$6-$B$14)/$B$11 -> 180000 | G22: =($B$6-$B$14)/$B$11 -> 180000 | H22: =($B$6-$B$14)/$B$11 -> 180000 | I22: =($B$6-$B$14)/$B$11 -> 180000 | J22: =($B$6-$B$14)/$B$11 -> 180000 | ... L22: =($B$6-$B$14)/$B$11 -> 180000
A23: Taxes | C23: =MAX(0,(C21-C22)*$B$13) -> 57500 | D23: =MAX(0,(D21-D22)*$B$13) -> 67400 | E23: =MAX(0,(E21-E22)*$B$13) -> 77894 | F23: =MAX(0,(F21-F22)*$B$13) -> 89017.64 | G23: =MAX(0,(G21-G22)*$B$13) -> 100808.7 | H23: =MAX(0,(H21-H22)*$B$13) -> 113307.22 | I23: =MAX(0,(I21-I22)*$B$13) -> 126555.65 | J23: =MAX(0,(J21-J22)*$B$13) -> 140598.99 | ... L23: =MAX(0,(L21-L22)*$B$13) -> 171264.03
A24: Salvage value | C24: 0 | D24: 0 | E24: 0 | F24: 0 | G24: 0 | H24: 0 | I24: 0 | J24: 0 | K24: 0 | L24: =$B$14 -> 200000
A25: Net cash flow | B25: =-$B$6 -> -2000000 | C25: =C21-C23+C24 -> 352500 | D25: =D21-D23+D24 -> 382200 | E25: =E21-E23+E24 -> 413682 | F25: =F21-F23+F24 -> 447052.92 | G25: =G21-G23+G24 -> 482426.1 | H25: =H21-H23+H24 -> 519921.66 | I25: =I21-I23+I24 -> 559666.96 | J25: =J21-J23+J24 -> 601796.98 | ... L25: =L21-L23+L24 -> 893792.08
A26: Cumulative cash flow | B26: =B25 -> -2000000 | C26: =B26+C25 -> -1647500 | D26: =C26+D25 -> -1265300 | E26: =D26+E25 -> -851618 | F26: =E26+F25 -> -404565.08 | G26: =F26+G25 -> 77861.015 | H26: =G26+H25 -> 597782.68 | I26: =H26+I25 -> 1157449.6 | J26: =I26+J25 -> 1759246.6 | ... L26: =K26+L25 -> 3299493.5
A27: Payback (helper) | C27: =IF(AND(B26<0,C26>=0),0-B26/C25,0) -> 0 | D27: =IF(AND(C26<0,D26>=0),1-C26/D25,0) -> 0 | E27: =IF(AND(D26<0,E26>=0),2-D26/E25,0) -> 0 | F27: =IF(AND(E26<0,F26>=0),3-E26/F25,0) -> 0 | G27: =IF(AND(F26<0,G26>=0),4-F26/G25,0) -> 4.8386053 | H27: =IF(AND(G26<0,H26>=0),5-G26/H25,0) -> 0 | I27: =IF(AND(H26<0,I26>=0),6-H26/I25,0) -> 0 | J27: =IF(AND(I26<0,J26>=0),7-I26/J25,0) -> 0 | K27: =IF(AND(J26<0,K26>=0),8-J26/K25,0) -> 0 | L27: =IF(AND(K26<0,L26>=0),9-K26/L25,0) -> 0
A28: Discounted cash flow | B28: =B25 -> -2000000 | C28: =C25/(1+$B$12)^1 -> 320454.55 | D28: =D25/(1+$B$12)^2 -> 315867.77 | E28: =E25/(1+$B$12)^3 -> 310805.41 | F28: =F25/(1+$B$12)^4 -> 305343.16 | G28: =G25/(1+$B$12)^5 -> 299548.65 | H28: =H25/(1+$B$12)^6 -> 293482.22 | I28: =I25/(1+$B$12)^7 -> 287197.64 | J28: =J25/(1+$B$12)^8 -> 280742.73 | K28: =K25/(1+$B$12)^9 -> 274159.94 | L28: =L25/(1+$B$12)^10 -> 344595.54
A29: Cumulative discounted cash flow | B29: =B28 -> -2000000 | C29: =B29+C28 -> -1679545.5 | D29: =C29+D28 -> -1363677.7 | E29: =D29+E28 -> -1052872.3 | F29: =E29+F28 -> -747529.12 | G29: =F29+G28 -> -447980.47 | H29: =G29+H28 -> -154498.24 | I29: =H29+I28 -> 132699.4 | J29: =I29+J28 -> 413442.13 | ... L29: =K29+L28 -> 1032197.6
A30: Discounted payback (helper) | C30: =IF(AND(B29<0,C29>=0),0-B29/C28,0) -> 0 | D30: =IF(AND(C29<0,D29>=0),1-C29/D28,0) -> 0 | E30: =IF(AND(D29<0,E29>=0),2-D29/E28,0) -> 0 | F30: =IF(AND(E29<0,F29>=0),3-E29/F28,0) -> 0 | G30: =IF(AND(F29<0,G29>=0),4-F29/G28,0) -> 0 | H30: =IF(AND(G29<0,H29>=0),5-G29/H28,0) -> 0 | I30: =IF(AND(H29<0,I29>=0),6-H29/I28,0) -> 6.5379509 | J30: =IF(AND(I29<0,J29>=0),7-I29/J28,0) -> 0 | K30: =IF(AND(J29<0,K29>=0),8-J29/K28,0) -> 0 | L30: =IF(AND(K29<0,L29>=0),9-K29/L28,0) -> 0
A32: Results
A33: Net present value (NPV) | B33: =B25+NPV($B$12,C25:L25) -> 1032197.6
A34: Internal rate of return (IRR) | B34: =IRR(B25:L25) -> 0.19335234
A35: Payback period | B35: =IF(SUM(C27:L27)=0,"Never",SUM(C27:L27)) -> 4.8386053
A36: Discounted payback period | B36: =IF(SUM(C30:L30)=0,"Never",SUM(C30:L30)) -> 6.5379509
A37: Profitability index | B37: =NPV($B$12,C25:L25)/$B$6 -> 1.5160988
A38: Break-even revenue per year | B38: =$B$10/(1-$B$9) -> 454545.45
A40: Sensitivity (calculated at export)
A41: Scenario | B41: NPV | C41: IRR | D41: Payback (yrs)
A42: Revenue −20% | B42: 266059.66 | C42: 0.12554053 | D42: 6.221294
A43: Revenue −10% | B43: 649128.64 | C43: 0.16035311 | D43: 5.44343
A44: Base case | B44: 1032197.6 | C44: 0.19335234 | D44: 4.8386053
...

Sheet Ratios
A1: Ratio Analysis
A2: Aurora Retail Co. · calculated from Historicals
A3: Blue = input you can change · Green = linked to Historicals · Black = formula
A5: Ratios by year
A6: Ratio | B6: 2020 | C6: 2021 | D6: 2022 | E6: 2023 | F6: 2024
A7: Revenue growth | C7: =IFERROR(Historicals!C7/Historicals!B7-1,"") -> 0.1097561 | D7: =IFERROR(Historicals!D7/Historicals!C7-1,"") -> 0.14285714 | E7: =IFERROR(Historicals!E7/Historicals!D7-1,"") -> 0.13461538 | F7: =IFERROR(Historicals!F7/Historicals!E7-1,"") -> 0.11016949
A8: Gross margin | B8: =IFERROR(Historicals!B9/Historicals!B7,"") -> 0.40243902 | C8: =IFERROR(Historicals!C9/Historicals!C7,"") -> 0.40659341 | D8: =IFERROR(Historicals!D9/Historicals!D7,"") -> 0.41346154 | E8: =IFERROR(Historicals!E9/Historicals!E7,"") -> 0.42372881 | F8: =IFERROR(Historicals!F9/Historicals!F7,"") -> 0.42748092
A9: EBITDA margin | B9: =IFERROR(Historicals!B11/Historicals!B7,"") -> 0.18292683 | C9: =IFERROR(Historicals!C11/Historicals!C7,"") -> 0.19230769 | D9: =IFERROR(Historicals!D11/Historicals!D7,"") -> 0.20673077 | E9: =IFERROR(Historicals!E11/Historicals!E7,"") -> 0.22033898 | F9: =IFERROR(Historicals!F11/Historicals!F7,"") -> 0.22900763
A10: Net margin | B10: =IFERROR(Historicals!B15/Historicals!B7,"") -> 0.093292683 | C10: =IFERROR(Historicals!C15/Historicals!C7,"") -> 0.10302198 | D10: =IFERROR(Historicals!D15/Historicals!D7,"") -> 0.11754808 | E10: =IFERROR(Historicals!E15/Historicals!E7,"") -> 0.13029661 | F10: =IFERROR(Historicals!F15/Historicals!F7,"") -> 0.13854962
A11: Current ratio | B11: =IFERROR(Historicals!B17/Historicals!B19,"") -> 1.6315789 | C11: =IFERROR(Historicals!C17/Historicals!C19,"") -> 1.75 | D11: =IFERROR(Historicals!D17/Historicals!D19,"") -> 1.8181818 | E11: =IFERROR(Historicals!E17/Historicals!E19,"") -> 1.9166667 | F11: =IFERROR(Historicals!F17/Historicals!F19,"") -> 2.0384615
A12: Debt / Equity | B12: =IFERROR(Historicals!B21/Historicals!B22,"") -> 0.73170732 | C12: =IFERROR(Historicals!C21/Historicals!C22,"") -> 0.57142857 | D12: =IFERROR(Historicals!D21/Historicals!D22,"") -> 0.44067797 | E12: =IFERROR(Historicals!E21/Historicals!E22,"") -> 0.34285714 | F12: =IFERROR(Historicals!F21/Historicals!F22,"") -> 0.26829268
A13: Debt / EBITDA | B13: =IFERROR(Historicals!B21/Historicals!B11,"") -> 2 | C13: =IFERROR(Historicals!C21/Historicals!C11,"") -> 1.6 | D13: =IFERROR(Historicals!D21/Historicals!D11,"") -> 1.2093023 | E13: =IFERROR(Historicals!E21/Historicals!E11,"") -> 0.92307692 | F13: =IFERROR(Historicals!F21/Historicals!F11,"") -> 0.73333333
A14: Interest coverage (EBIT / interest) | B14: =IFERROR(Historicals!B13/Historicals!B14,"") -> 6.6666667 | C14: =IFERROR(Historicals!C13/Historicals!C14,"") -> 8.3529412 | D14: =IFERROR(Historicals!D13/Historicals!D14,"") -> 11.1875 | E14: =IFERROR(Historicals!E13/Historicals!E14,"") -> 14.666667 | F14: =IFERROR(Historicals!F13/Historicals!F14,"") -> 18.285714
A15: Return on assets | B15: =IFERROR(Historicals!B15/Historicals!B18,"") -> 0.080526316 | C15: =IFERROR(Historicals!C15/Historicals!C18,"") -> 0.091019417 | D15: =IFERROR(Historicals!D15/Historicals!D18,"") -> 0.10723684 | E15: =IFERROR(Historicals!E15/Historicals!E18,"") -> 0.12202381 | F15: =IFERROR(Historicals!F15/Historicals!F18,"") -> 0.12964286
A16: Return on equity | B16: =IFERROR(Historicals!B15/Historicals!B22,"") -> 0.18658537 | C16: =IFERROR(Historicals!C15/Historicals!C22,"") -> 0.19132653 | D16: =IFERROR(Historicals!D15/Historicals!D22,"") -> 0.20720339 | E16: =IFERROR(Historicals!E15/Historicals!E22,"") -> 0.21964286 | F16: =IFERROR(Historicals!F15/Historicals!F22,"") -> 0.22134146
A17: Cash conversion (OCF / net income) | B17: =IFERROR(Historicals!B24/Historicals!B15,"") -> 1.5686275 | C17: =IFERROR(Historicals!C24/Historicals!C15,"") -> 1.4933333 | D17: =IFERROR(Historicals!D24/Historicals!D15,"") -> 1.390593 | E17: =IFERROR(Historicals!E24/Historicals!E15,"") -> 1.300813 | F17: =IFERROR(Historicals!F24/Historicals!F15,"") -> 1.322314

Sheet Forecast
A1: 3-Statement Forecast
A2: Aurora Retail Co. · projected financials
A3: Blue = input you can change · Green = linked to Historicals · Black = formula
A5: Assumptions
A6: Base revenue (last actual year) | B6: =Historicals!$F$7 -> 13100000
A7: Revenue growth | B7: 0.124
A8: Gross margin | B8: 0.427
A9: Operating expenses % of revenue | B9: 0.198
A10: D&A % of revenue | B10: 0.034
A11: CapEx % of revenue | B11: 0.061
A12: Opening debt | B12: =Historicals!$F$21 -> 2200000
A13: Debt repaid per year | B13: 220000
A14: Interest rate | B14: 0.064
A15: Opening cash | B15: =Historicals!$F$16 -> 2300000
A16: Tax rate | B16: 0.25
A18: Projected financial statements
B19: 2024A | C19: 2025E | D19: 2026E | E19: 2027E | F19: 2028E | G19: 2029E
A20: Revenue | B20: =$B$6 -> 13100000 | C20: =B20*(1+$B$7) -> 14724400 | D20: =C20*(1+$B$7) -> 16550226 | E20: =D20*(1+$B$7) -> 18602454 | F20: =E20*(1+$B$7) -> 20909158 | G20: =F20*(1+$B$7) -> 23501893
A21: Gross profit | C21: =C20*$B$8 -> 6287318.8 | D21: =D20*$B$8 -> 7066946.3 | E21: =E20*$B$8 -> 7943247.7 | F21: =F20*$B$8 -> 8928210.4 | G21: =G20*$B$8 -> 10035308
A22: Operating expenses | C22: =C20*$B$9 -> 2915431.2 | D22: =D20*$B$9 -> 3276944.7 | E22: =E20*$B$9 -> 3683285.8 | F22: =F20*$B$9 -> 4140013.2 | G22: =G20*$B$9 -> 4653374.9
A23: EBITDA | C23: =C21-C22 -> 3371887.6 | D23: =D21-D22 -> 3790001.7 | E23: =E21-E22 -> 4259961.9 | F23: =F21-F22 -> 4788197.1 | G23: =G21-G22 -> 5381933.6
A24: Depreciation & amortization | C24: =C20*$B$10 -> 500629.6 | D24: =D20*$B$10 -> 562707.67 | E24: =E20*$B$10 -> 632483.42 | F24: =F20*$B$10 -> 710911.37 | G24: =G20*$B$10 -> 799064.38
A25: EBIT | C25: =C23-C24 -> 2871258 | D25: =D23-D24 -> 3227294 | E25: =E23-E24 -> 3627478.4 | F25: =F23-F24 -> 4077285.8 | G25: =G23-G24 -> 4582869.2
A26: Interest expense | C26: =B32*$B$14 -> 140800 | D26: =C32*$B$14 -> 126720 | E26: =D32*$B$14 -> 112640 | F26: =E32*$B$14 -> 98560 | G26: =F32*$B$14 -> 84480
A27: Profit before tax | C27: =C25-C26 -> 2730458 | D27: =D25-D26 -> 3100574 | E27: =E25-E26 -> 3514838.4 | F27: =F25-F26 -> 3978725.8 | G27: =G25-G26 -> 4498389.2
A28: Taxes | C28: =MAX(0,C27*$B$16) -> 682614.5 | D28: =MAX(0,D27*$B$16) -> 775143.5 | E28: =MAX(0,E27*$B$16) -> 878709.61 | F28: =MAX(0,F27*$B$16) -> 994681.44 | G28: =MAX(0,G27*$B$16) -> 1124597.3
A29: Net income | C29: =C27-C28 -> 2047843.5 | D29: =D27-D28 -> 2325430.5 | E29: =E27-E28 -> 2636128.8 | F29: =F27-F28 -> 2984044.3 | G29: =G27-G28 -> 3373791.9
A30: Capital expenditure | C30: =C20*$B$11 -> 898188.4 | D30: =D20*$B$11 -> 1009563.8 | E30: =E20*$B$11 -> 1134749.7 | F30: =F20*$B$11 -> 1275458.6 | G30: =G20*$B$11 -> 1433615.5
A31: Debt repayment | C31: =MIN(B32,$B$13) -> 220000 | D31: =MIN(C32,$B$13) -> 220000 | E31: =MIN(D32,$B$13) -> 220000 | F31: =MIN(E32,$B$13) -> 220000 | G31: =MIN(F32,$B$13) -> 220000
A32: Closing debt | B32: =$B$12 -> 2200000 | C32: =B32-C31 -> 1980000 | D32: =C32-D31 -> 1760000 | E32: =D32-E31 -> 1540000 | F32: =E32-F31 -> 1320000 | G32: =F32-G31 -> 1100000
A33: Closing cash | B33: =$B$15 -> 2300000 | C33: =B33+C29+C24-C30-C31 -> 3730284.7 | D33: =C33+D29+D24-D30-D31 -> 5388859.1 | E33: =D33+E29+E24-E30-E31 -> 7302721.7 | F33: =E33+F29+F24-F30-F31 -> 9502218.8 | G33: =F33+G29+G24-G30-G31 -> 12021460
